[INFO   ] Logger: Record log in /storage/emulated/0/organizer/.kivy/logs/kivy_20-06-10_1.txt
[INFO   ] Kivy: v1.11.0.dev0, git-8b6af30, 20190320
[INFO   ] Python: v3.7.2 (default, Mar 20 2019, 15:02:54) 
[GCC 8.2.0]
[INFO   ] KivyMD: v0.104.1
[INFO   ] Factory: 184 symbols loaded
[INFO   ] Image: Providers: img_tex, img_dds, img_sdl2, img_pil, img_gif (img_ffpyplayer ignored)
[INFO   ] Window: Provider: sdl2
[INFO   ] GL: Using the "OpenGL ES 2" graphics system
[INFO   ] GL: Backend used <sdl2>
[INFO   ] GL: OpenGL version <b'OpenGL ES 3.2 V@331.0 (GIT@50f1b2d, I1b05bd271c) (Date:04/09/19)'>
[INFO   ] GL: OpenGL vendor <b'Qualcomm'>
[INFO   ] GL: OpenGL renderer <b'Adreno (TM) 505'>
[INFO   ] GL: OpenGL parsed version: 3, 2
[INFO   ] GL: Texture max size <16384>
[INFO   ] GL: Texture max units <16>
[INFO   ] Window: auto add sdl2 input provider
[INFO   ] Window: virtual keyboard not allowed, single mode, not docked
[INFO   ] Text: Provider: sdl2
[INFO   ] GL: NPOT texture support is available
[WARNING] Base: Unknown <android> provider
[INFO   ] Base: Start application main loop
[INFO   ] Base: Leaving application in progress...
[WARNING] stderr: Traceback (most recent call last):
[WARNING] stderr:   File "/data/user/0/ru.iiec.pydroid3/files/aarch64-linux-android/lib/python3.7/site-packages/urllib3/connection.py", line 157, in _new_conn
[WARNING] stderr:     (self._dns_host, self.port), self.timeout, **extra_kw
[WARNING] stderr:   File "/data/user/0/ru.iiec.pydroid3/files/aarch64-linux-android/lib/python3.7/site-packages/urllib3/util/connection.py", line 61, in create_connection
[WARNING] stderr:     for res in socket.getaddrinfo(host, port, family, socket.SOCK_STREAM):
[WARNING] stderr:   File "/data/user/0/ru.iiec.pydroid3/files/aarch64-linux-android/lib/python3.7/socket.py", line 748, in getaddrinfo
[WARNING] stderr:     for res in _socket.getaddrinfo(host, port, family, type, proto, flags):
[WARNING] stderr: socket.gaierror: [Errno 7] No address associated with hostname
[WARNING] stderr: 
[WARNING] stderr: During handling of the above exception, another exception occurred:
[WARNING] stderr: 
[WARNING] stderr: Traceback (most recent call last):
[WARNING] stderr:   File "/data/user/0/ru.iiec.pydroid3/files/aarch64-linux-android/lib/python3.7/site-packages/urllib3/connectionpool.py", line 672, in urlopen
[WARNING] stderr:     chunked=chunked,
[WARNING] stderr:   File "/data/user/0/ru.iiec.pydroid3/files/aarch64-linux-android/lib/python3.7/site-packages/urllib3/connectionpool.py", line 376, in _make_request
[WARNING] stderr:     self._validate_conn(conn)
[WARNING] stderr:   File "/data/user/0/ru.iiec.pydroid3/files/aarch64-linux-android/lib/python3.7/site-packages/urllib3/connectionpool.py", line 994, in _validate_conn
[WARNING] stderr:     conn.connect()
[WARNING] stderr:   File "/data/user/0/ru.iiec.pydroid3/files/aarch64-linux-android/lib/python3.7/site-packages/urllib3/connection.py", line 334, in connect
[WARNING] stderr:     conn = self._new_conn()
[WARNING] stderr:   File "/data/user/0/ru.iiec.pydroid3/files/aarch64-linux-android/lib/python3.7/site-packages/urllib3/connection.py", line 169, in _new_conn
[WARNING] stderr:     self, "Failed to establish a new connection: %s" % e
[WARNING] stderr: urllib3.exceptions.NewConnectionError: <urllib3.connection.VerifiedHTTPSConnection object at 0x7e5922d940>: Failed to establish a new connection: [Errno 7] No address associated with hostname
[WARNING] stderr: 
[WARNING] stderr: During handling of the above exception, another exception occurred:
[WARNING] stderr: 
[WARNING] stderr: Traceback (most recent call last):
[WARNING] stderr:   File "/data/user/0/ru.iiec.pydroid3/files/aarch64-linux-android/lib/python3.7/site-packages/requests/adapters.py", line 449, in send
[WARNING] stderr:     timeout=timeout
[WARNING] stderr:   File "/data/user/0/ru.iiec.pydroid3/files/aarch64-linux-android/lib/python3.7/site-packages/urllib3/connectionpool.py", line 720, in urlopen
[WARNING] stderr:     method, url, error=e, _pool=self, _stacktrace=sys.exc_info()[2]
[WARNING] stderr:   File "/data/user/0/ru.iiec.pydroid3/files/aarch64-linux-android/lib/python3.7/site-packages/urllib3/util/retry.py", line 436, in increment
[WARNING] stderr:     raise MaxRetryError(_pool, url, error or ResponseError(cause))
[WARNING] stderr: urllib3.exceptions.MaxRetryError: HTTPSConnectionPool(host='taskator12.firebaseio.com', port=443): Max retries exceeded with url: /@General/hand%20sanizer%20100ml%2030.json (Caused by NewConnectionError('<urllib3.connection.VerifiedHTTPSConnection object at 0x7e5922d940>: Failed to establish a new connection: [Errno 7] No address associated with hostname'))
[WARNING] stderr: 
[WARNING] stderr: During handling of the above exception, another exception occurred:
[WARNING] stderr: 
[WARNING] stderr: Traceback (most recent call last):
[WARNING] stderr:   File "/storage/emulated/0/organizer/nav.py", line 364, in <module>
[WARNING] stderr:     MyApp().run()
[WARNING] stderr:   File "/data/user/0/ru.iiec.pydroid3/files/aarch64-linux-android/lib/python3.7/site-packages/kivy/app.py", line 826, in run
[WARNING] stderr:     runTouchApp()
[WARNING] stderr:   File "/data/user/0/ru.iiec.pydroid3/files/aarch64-linux-android/lib/python3.7/site-packages/kivy/base.py", line 502, in runTouchApp
[WARNING] stderr:     EventLoop.window.mainloop()
[WARNING] stderr:   File "/data/user/0/ru.iiec.pydroid3/files/aarch64-linux-android/lib/python3.7/site-packages/kivy/core/window/window_sdl2.py", line 724, in mainloop
[WARNING] stderr:     self._mainloop()
[WARNING] stderr:   File "/data/user/0/ru.iiec.pydroid3/files/aarch64-linux-android/lib/python3.7/site-packages/kivy/core/window/window_sdl2.py", line 459, in _mainloop
[WARNING] stderr:     EventLoop.idle()
[WARNING] stderr:   File "/data/user/0/ru.iiec.pydroid3/files/aarch64-linux-android/lib/python3.7/site-packages/kivy/base.py", line 340, in idle
[WARNING] stderr:     self.dispatch_input()
[WARNING] stderr:   File "/data/user/0/ru.iiec.pydroid3/files/aarch64-linux-android/lib/python3.7/site-packages/kivy/base.py", line 325, in dispatch_input
[WARNING] stderr:     post_dispatch_input(*pop(0))
[WARNING] stderr:   File "/data/user/0/ru.iiec.pydroid3/files/aarch64-linux-android/lib/python3.7/site-packages/kivy/base.py", line 291, in post_dispatch_input
[WARNING] stderr:     wid.dispatch('on_touch_up', me)
[WARNING] stderr:   File "kivy/_event.pyx", line 707, in kivy._event.EventDispatcher.dispatch
[WARNING] stderr:   File "/data/user/0/ru.iiec.pydroid3/files/aarch64-linux-android/lib/python3.7/site-packages/kivymd/uix/behaviors/ripplebehavior.py", line 245, in on_touch_up
[WARNING] stderr:     return super().on_touch_up(touch)
[WARNING] stderr:   File "/data/user/0/ru.iiec.pydroid3/files/aarch64-linux-android/lib/python3.7/site-packages/kivymd/uix/button.py", line 1083, in on_touch_up
[WARNING] stderr:     return super().on_touch_up(touch)
[WARNING] stderr:   File "/data/user/0/ru.iiec.pydroid3/files/aarch64-linux-android/lib/python3.7/site-packages/kivy/uix/behaviors/button.py", line 179, in on_touch_up
[WARNING] stderr:     self.dispatch('on_release')
[WARNING] stderr:   File "kivy/_event.pyx", line 703, in kivy._event.EventDispatcher.dispatch
[WARNING] stderr:   File "kivy/_event.pyx", line 1214, in kivy._event.EventObservers.dispatch
[WARNING] stderr:   File "kivy/_event.pyx", line 1138, in kivy._event.EventObservers._dispatch
[WARNING] stderr:   File "/data/user/0/ru.iiec.pydroid3/files/aarch64-linux-android/lib/python3.7/site-packages/kivymd/uix/button.py", line 1637, in <lambda>
[WARNING] stderr:     on_release=lambda x=bottom_button: self.callback(x)
[WARNING] stderr:   File "/storage/emulated/0/organizer/nav.py", line 183, in callback_tab
[WARNING] stderr:     self.delete_selected_notes(self.selected_notes)
[WARNING] stderr:   File "/storage/emulated/0/organizer/nav.py", line 247, in delete_selected_notes
[WARNING] stderr:     requests.delete(url=MyApp.url[:-5]+key+'/'+item.text+'.json')
[WARNING] stderr:   File "/data/user/0/ru.iiec.pydroid3/files/aarch64-linux-android/lib/python3.7/site-packages/requests/api.py", line 158, in delete
[WARNING] stderr:     return request('delete', url, **kwargs)
[WARNING] stderr:   File "/data/user/0/ru.iiec.pydroid3/files/aarch64-linux-android/lib/python3.7/site-packages/requests/api.py", line 60, in request
[WARNING] stderr:     return session.request(method=method, url=url, **kwargs)
[WARNING] stderr:   File "/data/user/0/ru.iiec.pydroid3/files/aarch64-linux-android/lib/python3.7/site-packages/requests/sessions.py", line 533, in request
[WARNING] stderr:     resp = self.send(prep, **send_kwargs)
[WARNING] stderr:   File "/data/user/0/ru.iiec.pydroid3/files/aarch64-linux-android/lib/python3.7/site-packages/requests/sessions.py", line 646, in send
[WARNING] stderr:     r = adapter.send(request, **kwargs)
[WARNING] stderr:   File "/data/user/0/ru.iiec.pydroid3/files/aarch64-linux-android/lib/python3.7/site-packages/requests/adapters.py", line 516, in send
[WARNING] stderr:     raise ConnectionError(e, request=request)
[WARNING] stderr: requests.exceptions.ConnectionError: HTTPSConnectionPool(host='taskator12.firebaseio.com', port=443): Max retries exceeded with url: /@General/hand%20sanizer%20100ml%2030.json (Caused by NewConnectionError('<urllib3.connection.VerifiedHTTPSConnection object at 0x7e5922d940>: Failed to establish a new connection: [Errno 7] No address associated with hostname'))
