[INFO   ] Logger: Record log in /storage/emulated/0/organizer/.kivy/logs/kivy_20-06-13_8.txt
[INFO   ] Kivy: v1.11.0.dev0, git-8b6af30, 20190320
[INFO   ] Python: v3.7.2 (default, Mar 20 2019, 15:02:54) 
[GCC 8.2.0]
[INFO   ] KivyMD: v0.104.1
[INFO   ] Factory: 184 symbols loaded
[INFO   ] Image: Providers: img_tex, img_dds, img_sdl2, img_pil, img_gif (img_ffpyplayer ignored)
[INFO   ] Window: Provider: sdl2
[INFO   ] GL: Using the "OpenGL ES 2" graphics system
[INFO   ] GL: Backend used <sdl2>
[INFO   ] GL: OpenGL version <b'OpenGL ES 3.2 V@331.0 (GIT@50f1b2d, I1b05bd271c) (Date:04/09/19)'>
[INFO   ] GL: OpenGL vendor <b'Qualcomm'>
[INFO   ] GL: OpenGL renderer <b'Adreno (TM) 505'>
[INFO   ] GL: OpenGL parsed version: 3, 2
[INFO   ] GL: Texture max size <16384>
[INFO   ] GL: Texture max units <16>
[INFO   ] Window: auto add sdl2 input provider
[INFO   ] Window: virtual keyboard not allowed, single mode, not docked
[INFO   ] Text: Provider: sdl2
[INFO   ] GL: NPOT texture support is available
[WARNING] stderr: Traceback (most recent call last):
[WARNING] stderr:   File "/data/user/0/ru.iiec.pydroid3/files/aarch64-linux-android/lib/python3.7/site-packages/urllib3/connection.py", line 157, in _new_conn
[WARNING] stderr:     (self._dns_host, self.port), self.timeout, **extra_kw
[WARNING] stderr:   File "/data/user/0/ru.iiec.pydroid3/files/aarch64-linux-android/lib/python3.7/site-packages/urllib3/util/connection.py", line 61, in create_connection
[WARNING] stderr:     for res in socket.getaddrinfo(host, port, family, socket.SOCK_STREAM):
[WARNING] stderr:   File "/data/user/0/ru.iiec.pydroid3/files/aarch64-linux-android/lib/python3.7/socket.py", line 748, in getaddrinfo
[WARNING] stderr:     for res in _socket.getaddrinfo(host, port, family, type, proto, flags):
[WARNING] stderr: socket.gaierror: [Errno 7] No address associated with hostname
[WARNING] stderr: 
[WARNING] stderr: During handling of the above exception, another exception occurred:
[WARNING] stderr: 
[WARNING] stderr: Traceback (most recent call last):
[WARNING] stderr:   File "/data/user/0/ru.iiec.pydroid3/files/aarch64-linux-android/lib/python3.7/site-packages/urllib3/connectionpool.py", line 672, in urlopen
[WARNING] stderr:     chunked=chunked,
[WARNING] stderr:   File "/data/user/0/ru.iiec.pydroid3/files/aarch64-linux-android/lib/python3.7/site-packages/urllib3/connectionpool.py", line 376, in _make_request
[WARNING] stderr:     self._validate_conn(conn)
[WARNING] stderr:   File "/data/user/0/ru.iiec.pydroid3/files/aarch64-linux-android/lib/python3.7/site-packages/urllib3/connectionpool.py", line 994, in _validate_conn
[WARNING] stderr:     conn.connect()
[WARNING] stderr:   File "/data/user/0/ru.iiec.pydroid3/files/aarch64-linux-android/lib/python3.7/site-packages/urllib3/connection.py", line 334, in connect
[WARNING] stderr:     conn = self._new_conn()
[WARNING] stderr:   File "/data/user/0/ru.iiec.pydroid3/files/aarch64-linux-android/lib/python3.7/site-packages/urllib3/connection.py", line 169, in _new_conn
[WARNING] stderr:     self, "Failed to establish a new connection: %s" % e
[WARNING] stderr: urllib3.exceptions.NewConnectionError: <urllib3.connection.VerifiedHTTPSConnection object at 0x7e5e4dddd8>: Failed to establish a new connection: [Errno 7] No address associated with hostname
[WARNING] stderr: 
[WARNING] stderr: During handling of the above exception, another exception occurred:
[WARNING] stderr: 
[WARNING] stderr: Traceback (most recent call last):
[WARNING] stderr:   File "/data/user/0/ru.iiec.pydroid3/files/aarch64-linux-android/lib/python3.7/site-packages/requests/adapters.py", line 449, in send
[WARNING] stderr:     timeout=timeout
[WARNING] stderr:   File "/data/user/0/ru.iiec.pydroid3/files/aarch64-linux-android/lib/python3.7/site-packages/urllib3/connectionpool.py", line 720, in urlopen
[WARNING] stderr:     method, url, error=e, _pool=self, _stacktrace=sys.exc_info()[2]
[WARNING] stderr:   File "/data/user/0/ru.iiec.pydroid3/files/aarch64-linux-android/lib/python3.7/site-packages/urllib3/util/retry.py", line 436, in increment
[WARNING] stderr:     raise MaxRetryError(_pool, url, error or ResponseError(cause))
[WARNING] stderr: urllib3.exceptions.MaxRetryError: HTTPSConnectionPool(host='jonesoil.ie', port=443): Max retries exceeded with url: /api/get_banded_oil_prices/product/1/quantity/1000 (Caused by NewConnectionError('<urllib3.connection.VerifiedHTTPSConnection object at 0x7e5e4dddd8>: Failed to establish a new connection: [Errno 7] No address associated with hostname'))
[WARNING] stderr: 
[WARNING] stderr: During handling of the above exception, another exception occurred:
[WARNING] stderr: 
[WARNING] stderr: Traceback (most recent call last):
[WARNING] stderr:   File "/storage/emulated/0/organizer/nav.py", line 286, in <module>
[WARNING] stderr:     class CaroseneScreen(Screen):
[WARNING] stderr:   File "/storage/emulated/0/organizer/nav.py", line 297, in CaroseneScreen
[WARNING] stderr:     headers={"User-Agent":"Mozilla/5.0"})
[WARNING] stderr:   File "/data/user/0/ru.iiec.pydroid3/files/aarch64-linux-android/lib/python3.7/site-packages/requests/api.py", line 116, in post
[WARNING] stderr:     return request('post', url, data=data, json=json, **kwargs)
[WARNING] stderr:   File "/data/user/0/ru.iiec.pydroid3/files/aarch64-linux-android/lib/python3.7/site-packages/requests/api.py", line 60, in request
[WARNING] stderr:     return session.request(method=method, url=url, **kwargs)
[WARNING] stderr:   File "/data/user/0/ru.iiec.pydroid3/files/aarch64-linux-android/lib/python3.7/site-packages/requests/sessions.py", line 533, in request
[WARNING] stderr:     resp = self.send(prep, **send_kwargs)
[WARNING] stderr:   File "/data/user/0/ru.iiec.pydroid3/files/aarch64-linux-android/lib/python3.7/site-packages/requests/sessions.py", line 646, in send
[WARNING] stderr:     r = adapter.send(request, **kwargs)
[WARNING] stderr:   File "/data/user/0/ru.iiec.pydroid3/files/aarch64-linux-android/lib/python3.7/site-packages/requests/adapters.py", line 516, in send
[WARNING] stderr:     raise ConnectionError(e, request=request)
[WARNING] stderr: requests.exceptions.ConnectionError: HTTPSConnectionPool(host='jonesoil.ie', port=443): Max retries exceeded with url: /api/get_banded_oil_prices/product/1/quantity/1000 (Caused by NewConnectionError('<urllib3.connection.VerifiedHTTPSConnection object at 0x7e5e4dddd8>: Failed to establish a new connection: [Errno 7] No address associated with hostname'))
